<?xml version="1.0"?>
<robot xmlns:xacro="http://www.ros.org/wiki/xacro" >

    <xacro:include filename="robot_materials.xacro" />

    <!-- BASE LINK -->

    <link name="base_link">

    </link>

    <!-- CHASSIS LINK -->

    <joint name="chassis_joint" type="fixed">
        <parent link="base_link"/>
        <child link="chassis"/>
        <origin xyz="-0.1 0 0"/>
    </joint>
    
    <link name="chassis">
        <visual>
            <origin xyz="0.39 0 0.075"/> 
            <geometry>
                <box size="0.78 0.6 0.15"/> 
            </geometry>
            <material name="white"/>
        </visual>
    </link>

    <!-- RIGHT WHEEL LINK -->

    <joint name="right_wheel_joint" type="continuous">
        <parent link="base_link"/>
        <child link="right_wheel"/>
        <origin xyz="0 -0.2125 0" rpy="${pi/2} 0 0"/>
        <axis xyz="0 0 -1"/>
    </joint>
    
    <link name="right_wheel">
        <visual>
            <geometry>
                <cylinder radius="0.1" length="0.04"/> 
            </geometry>
            <material name="orange"/>
        </visual>
    </link>

    <!-- LEFT WHEEL LINK -->

    <joint name="left_wheel_joint" type="continuous">
        <parent link="base_link"/>
        <child link="left_wheel"/>
        <origin xyz="0 0.2125 0" rpy="-${pi/2} 0 0"/>
        <axis xyz="0 0 1"/>
    </joint>
    
    <link name="left_wheel">
        <visual>
            <geometry>
                <cylinder radius="0.1" length="0.04"/> 
            </geometry>
            <material name="orange"/>
        </visual>
    </link>


</robot>

<!-- sasiu 600, roti ext 463 => 232.5-20 212.5 => 0.2125 -->